The following error occurred while processing a celery task:

{{ traceback }}